/* Copyright (c) 2013 Billy Tetrud - Free to use for any purpose: MIT License*/

var trimArgs = require("trimArguments")

// todo:
// * timeout
// * Long stack traces

module.exports = Future

function Future() {
    this.resolved = false
    this.queue = []
}

// static methods

// has one parameter: either a bunch of futures, or a single array of futures
// returns a promise that resolves when one of them errors, or when all of them succeeds
Future.all = function() {
    if(arguments[0] instanceof Array) {
        var futures = arguments[0]
    } else {
        var futures = trimArgs(arguments)
    }

    var f = new Future()
    var results = []

    if(futures.length > 0) {
        var current = futures[0]
        futures.forEach(function(future, index) {
            current = current.then(function(v) {
                results[index] = v
                return futures[index+1]
            })
        })

        //if
        current.catch(function(e) {
            f.throw(e)
        })
        // else
        current.then(function() {
            f.return(results)
        })


    } else {
        f.return(results)
    }

    return f
}

// either used like futureWrap(function(){ ... })(arg1,arg2,etc) or
//  futureWrap(object, 'methodName')(arg1,arg2,etc)
Future.wrap = function() {
    // function
    if(arguments.length === 1) {
        var fn = arguments[0]
        var object = undefined


    // object, function
    } else {
        var object = arguments[0]
        var fn = object[arguments[1]]
    }

    return function() {
        var args = Array.prototype.slice.call(arguments)
        var future = new Future
        args.push(future.resolver())
        var me = this
        if(object) me = object
        fn.apply(me, args)
        return future
    }
}


// default
var unhandledErrorHandler = function(e) {
    setTimeout(function() { //  nextTick
        throw e
    },0)
}

// setup unhandled error handler
// unhandled errors happen when done is called, and  then an exception is thrown from the future
Future.error = function(handler) {
    unhandledErrorHandler = handler
}


// instance methods

// returns a value for the future (can only be executed once)
// if there are callbacks waiting on this value, they are run in the next tick
    // (ie they aren't run immediately, allowing the current thread of execution to complete)
Future.prototype.return = function(v) {
    resolve(this, 'return', v)
}
Future.prototype.throw = function(e) {
    resolve(this, 'error', e)
}
function setNext(that, future) {
    if((!future instanceof Future))
        unhandledErrorHandler(Error("Value returned from then or catch *not* a Future: "+result))
    resolve(that, 'next', future)
}

function wait(that, cb) {
    if(that.resolved) {
        executeCallbacks(that, [cb])
    } else {
        that.queue.push(cb)
    }
}

function waitOnResult(f, result, cb) {
    if(result !== undefined)
        wait(result, function() {
            if(this.hasError)
                f.throw(this.error)
            else {
                try {
                    setNext(f, cb(this.result))
                } catch(e) {
                    f.throw(e)
                }
            }
        })
    else
        f.return(cb())
}


// cb takes one parameter - the value returned
// cb can return a Future, in which case the result of that Future is passed to next-in-chain
Future.prototype.then = function(cb) {
    var f = new Future
    wait(this, function() {
        if(this.hasError)
            f.throw(this.error)
        else if(this.hasNext)
            waitOnResult(f, this.next, cb)
        else {
            try {
                setNext(f, cb(this.result))
            } catch(e) {
                f.throw(e)
            }
        }
    })
    return f
}
// cb takes one parameter - the error caught
// cb can return a Future, in which case the result of that Future is passed to next-in-chain
Future.prototype.catch = function(cb) {
    var f = new Future
    wait(this, function() {
        if(this.hasError) {
            try {
                setNext(f, cb(this.error))
            } catch(e) {
                f.throw(e)
            }
        } else if(this.hasNext)
            setNext(f, this.next)
        else
            f.return(this.result)
    })
    return f
}
// cb takes no parameters
// callback's return value is ignored, but thrown exceptions propogate normally
Future.prototype.finally = function(cb) {
    var f = new Future
    wait(this, function() {
        try {
            cb()
            if(this.hasError)
                f.throw(this.error)
            else {
                f.return(this.result)
            }
        } catch(e) {
            f.throw(e)
        }
    })
    return f
}

// all unused futures should end with this (e.g. most then-chains)
// detatches the future so any propogated exception is thrown (so the exception isn't silently lost)
Future.prototype.done = function() {
    wait(this, function() {
        if(this.hasError) {
            unhandledErrorHandler(this.error)
        }
    })
}



Future.prototype.resolver = function() {
    var me = this

    return function(e,v) {
        if(e) { // error argument
            me.throw(e)
        } else {
            me.return(v)
        }
    }
}

Future.prototype.isResolved = function() {
    return this.resolved
}


function resolve(that, type, value) {
    if(that.resolved)
        throw Error("Future resolved more than once! Resolution: "+value)

    that.resolved = true
    that.hasError = type === 'error'
    that.hasNext = type === 'next'

    if(that.hasError)
        that.error = value
    else if(that.hasNext)
        that.next = value
    else
        that.result = value

    executeCallbacks(that, that.queue)
}

function executeCallbacks(that, callbacks) {
    if(callbacks.length > 0) {
        setTimeout(function() {   // basically process.nextTick
            callbacks.forEach(function(cb) {
                cb.apply(that)
            })
        },0)
    }
}
